Workbook

Sheet INFORMACIÓN_GENERAL
B3: Evaluación del proyecto
D5: Facultad de Ingeniería y Diseño - Maestría en Ciencia de Datos/Inteligencia Artificial Aplicada - Evaluación Proyecto II de innovación tecnológica en IA
B11: Código del Proyecto | F11: NA
B12: Título del Proyecto | F12: Inserte el nombre del proyecto
B14: Nombre(s) Estudiante(s)
B22: Profesor del curso: | D22: Jose Moncada
B23: Nombre del Mentor:
B24: Nombre del Representante Empresa: | D24: NA

Sheet EVALUACION
D2: Facultad de Ingeniería y Diseño - Maestría en Ciencia de Datos/Inteligencia Artificial Aplicada - Evaluación Proyecto II de innovación tecnológica en IA
B8: Niveles de Proficiencia | C8: Valor Numérico
B9: Nivel 4: Excede el Estándar | C9: 5,0 - 4,5
B10: Nivel 3: Logra el Estándar | C10: 4,4 - 3,8
B11: Nivel 2: Se acerca al Estándar | C11: 3,7 - 3,0
B12: Nivel 1: NO cumple con el estándar | C12: 2,9 - 1.0
B15: EVALUACIÓN GENERAL
B16: Criterio | C16: Porcentaje | D16: Evaluador | F16: Detalle | G16: Ponderación | H16: Evaluación Numérica
D17: Empresa | E17: Mentor
B18: =Rúbrica!A11 -> Escritura del documento | C18: =SUM(G18:G21) -> 0.17 | E18: X | F18: =Rúbrica!B11 -> Ortografía, vocabulario, gramática. | G18: 0.04
E19: X | F19: =Rúbrica!B12 -> Cohesión y coherencia. | G19: 0.04
E20: X | F20: =Rúbrica!B13 -> Citaciones y Bibliografía | G20: 0.04
E21: X | F21: =Rúbrica!B14 -> Estructura IMRC | G21: 0.05
B22: =Rúbrica!A15 -> Fundamentación Teórica | C22: =SUM(G22:G23) -> 0.06 | E22: X | F22: =Rúbrica!B15 -> Marco Teórico | G22: 0.02
E23: X | F23: =Rúbrica!B16 -> Estado del Arte | G23: 0.04
B24: =Rúbrica!A17 -> Constitución del proyecto | C24: =SUM(G24:G26) -> 0.1 | E24: X | F24: =Rúbrica!B17 -> Formulación del Problema de Negocio (motivación y antecedentes). | G24: 0.04
E25: X | F25: =Rúbrica!B18 -> Objetivos | G25: 0.04
E26: X | F26: =Rúbrica!B19 -> Metodología | G26: 0.02
B27: =Rúbrica!A20 -> Aplicación de Ciencia de Datos | C27: =SUM(G27:G36) -> 0.37 | E27: X | F27: =Rúbrica!B20 -> Selección y estudio de viabilidad del dataset para un proyecto de ciencias de datos. | G27: 0.02
E28: X | F28: =Rúbrica!B21 -> Identificación del tipo de problema y del paradigma de IA adecuado para abordarlo. | G28: 0.02
E29: X | F29: =Rúbrica!B22 -> Revisión y justificación sobre el proceso de selección y descarte de features. | G29: 0.04
E30: X | F30: =Rúbrica!B23 -> Acciones de preprocesamiento y su justificación. | G30: 0.02
E31: X | F31: =Rúbrica!B24 -> Selección y justificación de los algoritmos de entrenamiento. | G31: 0.02
E32: X | F32: =Rúbrica!B25 -> Selección y justificación de las métricas de desempeño. | G32: 0.02
E33: X | F33: =Rúbrica!B26 -> Generación de modelos de IA. | G33: 0.02
E34: X | F34: =Rúbrica!B27 -> Estrategias de optimización para cada modelo. | G34: 0.02
E35: X | F35: =Rúbrica!B28 -> Comparativo de los modelos de IA a través de la discusión y análisis desde las métricas de desempeño. | G35: 0.04
E36: X | F36: =Rúbrica!B29 -> VoBO y feedback del stakeholder del sector industria. | G36: 0.15
B37: =Rúbrica!A30 -> Sustentación | C37: =SUM(G37:G40) -> 0.3 | E37: X | F37: =Rúbrica!B30 -> Presentación e Introducción | G37: 0.06
E38: X | F38: =Rúbrica!B31 -> Estructura de la presentación | G38: 0.04
E39: X | F39: =Rúbrica!B32 -> Dominio del Contenido y defensa de argumentos. | G39: 0.14
E40: X | F40: =Rúbrica!B33 -> Conclusiones y cierre de la presentación | G40: 0.06
B41: EVALUACIÓN | C41: =SUMPRODUCT(G18:G40,H18:H40) -> 0 | G41: =SUM(G18:G40) -> 1

Sheet Rúbrica
C3: Facultad de Ingeniería y Diseño - Maestría en Ciencia de Datos/Inteligencia Artificial Aplicada - Evaluación Proyecto II de innovación tecnológica en IA
B9: Niveles de Proficiencia | C9: Nivel 4: Excede el Estándar | D9: Nivel 3: Logra el Estándar | E9: Nivel 2: Se acerca al Estándar | F9: Nivel 1: NO cumple con el estándar | G9: Nivel de Proficiencia alcanzado | H9: Valor Numerico
B10: Valor Numérico | C10: 5,0-4,5 | D10: 4,4 - 3,8 | E10: 3,7- 3,0 | F10: 2,9 - 1.0 | H10: Total
A11: Escritura del documento | B11: Ortografía, vocabulario, gramática. | C11: El documento está escrito sin errores ortográficos y los autores usan un vocabulario técnico acorde con el dominio del problema. | D11: El documento está escrito sin notables errores ortográficos y los autores usan un vocabulario técnico acorde con el dominio del problema. | E11: La mayoría de las secciones del documento no tienen notables errores ortográficos, y en ellas, los autores utilizan un vocabulario técnico acorde con el dominio del problema. | F11: El documento tiene errores ortográficos en todas las secciones, y en ellas, los autores utilizan un vocabulario técnico acorde con el dominio del problema. Sin embargo, su utilización ofrece oportunidades de mejora | G11: =IF(H11>=4.5,4,IF(H11>=3.8,3,(IF(H11>=3,2,1)))) -> 1 | H11: =EVALUACION!H18 -> 0
B12: Cohesión y coherencia. | C12: Los párrafos del documento permiten desarrollar y comprender el tema, las ideas en los párrafos están conectadas adecuadamente | D12: En la mayoría de los párrafos del documento, las oraciones están conectadas adecuadamente facilitando el entendimiento del tema y el razonamiento que realiza el autor | E12: En algunos párrafos del documento, las oraciones no están conectadas adecuadamente, dificultando el entendimiento del tema y el razonamiento del autor | F12: En algunos párrafos del documento, las oraciones no están conectadas adecuadamente, impidiendo el entendimiento del tema y el razonamiento del autor | G12: =IF(H12>=4.5,4,IF(H12>=3.8,3,(IF(H12>=3,2,1)))) -> 1 | H12: =EVALUACION!H19 -> 0
B13: Citaciones y Bibliografía | C13: El documento utiliza producción ajena de manera apropiada (citación textual, ampliación, parafraseo), identifica la fuente, y emplea de forma consistente el formato de citación y referencia. | D13: El documento utiliza producción ajena de manera apropiada, identifica la fuente, pero en algunas citaciones no emplea de forma consistente el formato de citación y referencia. | E13: El documento utiliza producción ajena de manera apropiada, identifica la fuente, pero no emplea el formato de citación y referencia. | F13: El documento utiliza producción ajena de forma inadecuada y no emplea los formatos de citación en forma correcta | G13: =IF(H13>=4.5,4,IF(H13>=3.8,3,(IF(H13>=3,2,1)))) -> 1 | H13: =EVALUACION!H20 -> 0
B14: Estructura IMRC | C14: El documento utiliza fuentes de información indexada y no indexada (literatura Blanca y Gris) en un equlibrio adecuado | D14: El documento utiliza fuentes de información indexada y no indexada (literatura Blanca y Gris) predominando la información NO indexada (literatura gris) | E14: El documento utiliza fuentes de información indexada y no indexada (literatura Blanca y Gris) predominndo las fuentes de información no indexada y unas pocas referencias indexadas. | F14: El documento NO utiliza producción indexada, solo utiliza información no indexada (literatura gris). | G14: =IF(H14>=4.5,4,IF(H14>=3.8,3,(IF(H14>=3,2,1)))) -> 1 | H14: =EVALUACION!H21 -> 0
A15: Fundamentación Teórica | B15: Marco Teórico | C15: Identifica los fundamentos y conceptos teóricos del problema, los relaciona con el proyecto y cita las referencias bibliográficas correspondientes. | D15: Identifica los fundamentos y conceptos teóricos del problema, los relaciona parcialmente con el proyecto y cita las referencias bibliográficas correspondientes. | E15: Identifica los fundamentos y conceptos teóricos del problema, los relaciona de forma incorrecta con el proyecto y cita las referencias bibliográficas correspondientes. | F15: Identifica ALGUNOS fundamentos y conceptos teóricos del problema y cita las referencias bibliográficas correspondientes. | G15: =IF(H15>=4.5,4,IF(H15>=3.8,3,(IF(H15>=3,2,1)))) -> 1 | H15: =EVALUACION!H22 -> 0
B16: Estado del Arte | C16: Caracteriza y analiza alternativas de solución propuestas, cita las referencias bibliográficas correspondientes y justifica las razones por la cuales estas propuestas no dan solución al problema planteado en el contexto identificado. | D16: Caracteriza y analiza alternativas de solución propuestas, cita las referencias bibliográficas correspondientes y justifica las razones por la cuales estas propuestas no dan solución al problema planteado, sin embargo, no las relaciona correctamente con el contexto identificado. | E16: Caracteriza y analiza alternativas de solución propuestas, cita las referencias bibliográficas correspondientes y NO establece una justificación de las razones por la cuales estas propuestas no dan solución al problema planteado | F16: Caracteriza y analiza alternativas de solución propuestas y cita las referencias bibliográficas correspondientes | G16: =IF(H16>=4.5,4,IF(H16>=3.8,3,(IF(H16>=3,2,1)))) -> 1 | H16: =EVALUACION!H23 -> 0
A17: Constitución del proyecto | B17: Formulación del Problema de Negocio (motivación y antecedentes). | C17: En el documento, se formula el problema central, identificando correctamente las causas y los efectos. Las relaciones identificadas están correctamente establecidas. | D17: En el documento, se formula el problema central, identificando correctamente las causas y los efectos. En las relaciones identificadas, la mayoría están correctamente establecidas. | E17: En el documento, se formula el problema central, se identifican correctamente las causas y los efectos. En las relaciones identificadas, la mayoría están incorrectamente establecidas | F17: En el documento, se formula el problema central, se identifican correctamente las causas y los efectos, pero no se identifican las relaciones entre ellas | G17: =IF(H17>=4.5,4,IF(H17>=3.8,3,IF(H17>=3,2,1))) -> 1 | H17: =EVALUACION!H24 -> 0
B18: Objetivos | C18: En el documento, se formula el objetivo general a partir del problema central, los objetivos específicos se derivan del objetivo general y todos son verificables | D18: En el documento, se formula el objetivo general a partir del problema central, los objetivos específicos se derivan del objetivo general y la mayoría son verificables | E18: En el documento, se formula el objetivo general a partir del problema central, los objetivos específicos se derivan del objetivo general y la mayoría no son verificables | F18: En el documento, se formula el objetivo general a partir del problema central, algunos de los objetivos específicos no se derivan del objetivo general | G18: =IF(H18>=4.5,4,IF(H18>=3.8,3,IF(H18>=3,2,1))) -> 1 | H18: =EVALUACION!H25 -> 0
B19: Metodología | C19: En el desarrollo del proyecto, se aplica una metodología de ingeniería para dar solución al problema complejo propuesto. La ejecución del 100% de las fases/etapas de la metodología resultan totalmente evidenciables en el documento. | D19: En el desarrollo del proyecto, se aplica una metodología de ingeniería para dar solución al problema complejo propuesto. La ejecución de al menos el 80% de las fases/etapas de la metodología resultan evidenciable en el documento. | E19: En el desarrollo del proyecto, se aplica una metodología de ingeniería para dar solución al problema complejo propuesto. La ejecución de al menos el 60% de las fases/etapas de la metodología resulta evidenciables en el documento. | F19: En el desarrollo del proyecto, se aplica una metodología de ingeniería para dar solución al problema complejo propuesto. La ejecución de menos del 60% de las fases/etapas de la metodología resulta evidenciables en el documento. | G19: =IF(H19>=4.5,4,IF(H19>=3.8,3,IF(H19>=3,2,1))) -> 1 | H19: =EVALUACION!H26 -> 0
A20: Aplicación de Ciencia de Datos | B20: Selección y estudio de viabilidad del dataset para un proyecto de ciencias de datos. | C20: El proceso de selección y análisis del dataset demuestra pensamiento crítico, profundidad técnica y rigor metodológico. | D20: Se realizó un análisis de viabilidad que incluye calidad, volumen, formato, acceso y estructura de los datos. | E20: Se seleccionó un dataset relacionado con el problema, pero con limitaciones claras no abordadas. | F20: No se seleccionó un dataset adecuado o relevante para el problema planteado. | G20: =IF(H20>=4.5,4,IF(H20>=3.8,3,IF(H20>=3,2,1))) -> 1 | H20: =EVALUACION!H27 -> 0
B21: Identificación del tipo de problema y del paradigma de IA adecuado para abordarlo. | C21: El paradigma de IA elegido es óptimo, y la justificación incluye análisis comparativo con otros enfoques posibles. | D21: El paradigma de IA seleccionado es adecuado y está bien justificado. | E21: El paradigma de IA seleccionado es razonable, pero la justificación es limitada o basada en generalidades. | F21: No se identifica claramente el tipo de problema (clasificación, regresión, clustering, etc.). | G21: =IF(H21>=4.5,4,IF(H21>=3.8,3,IF(H21>=3,2,1))) -> 1 | H21: =EVALUACION!H28 -> 0
B22: Revisión y justificación sobre el proceso de selección y descarte de features. | C22: El proceso demuestra un alto nivel de razonamiento técnico, transparencia metodológica y comprensión del impacto de las features en el desempeño del modelo. | D22: Se aplica un proceso sistemático de selección y descarte de features, utilizando criterios técnicos (como análisis de correlación, importancia, multicolinealidad, etc.). | E22: Se realiza una selección/descarte parcial de features, pero sin metodología clara o con criterios poco justificados. | F22: No se realiza ningún proceso claro de selección o descarte de características (features). | G22: =IF(H22>=4.5,4,IF(H22>=3.8,3,IF(H22>=3,2,1))) -> 1 | H22: =EVALUACION!H29 -> 0
B23: Acciones de preprocesamiento y su justificación. | C23: Las acciones de preprocesamiento reflejan comprensión profunda del flujo de trabajo en ciencia de datos, del dominio del problema y de las implicaciones en el rendimiento del modelo. | D23: Se identifican y abordan adecuadamente los principales problemas del dataset (valores faltantes, escalado, codificación, etc.). | E23: Se realizan algunas acciones de preprocesamiento, pero de forma incompleta o con una lógica limitada. | F23: No se realiza ningún preprocesamiento o se hace de forma incorrecta. | G23: =IF(H23>=4.5,4,IF(H23>=3.8,3,IF(H23>=3,2,1))) -> 1 | H23: =EVALUACION!H30 -> 0
B24: Selección y justificación de los algoritmos de entrenamiento. | C24: Se realiza una comparación sistemática de distintos enfoques, incluyendo métricas de rendimiento, complejidad computacional, interpretabilidad y robustez. | D24: Se demuestra una comprensión sólida del funcionamiento de los algoritmos y su adecuación al contexto. | E24: Se selecciona al menos un algoritmo apropiado, pero con una justificación limitada o superficial. | F24: No se selecciona un algoritmo adecuado o se elige sin justificación alguna. | G24: =IF(H24>=4.5,4,IF(H24>=3.8,3,IF(H24>=3,2,1))) -> 1 | H24: =EVALUACION!H31 -> 0
B25: Selección y justificación de las métricas de desempeño. | C25: Se realiza una selección rigurosa y estratégica de las métricas, considerando aspectos como desbalance, costos del error, impacto en el dominio aplicado, y características del modelo. La justificación incluye análisis comparativo y argumentos técnicos sólidos. | D25: Se seleccionan métricas adecuadas al tipo de problema (e.g., precisión, recall, F1, AUC, RMSE, MAE) y al contexto del proyecto. | E25: Se seleccionan algunas métricas apropiadas, pero sin una justificación clara o específica. | F25: No se seleccionan métricas de evaluación o se utilizan métricas inadecuadas para el tipo de problema. | G25: =IF(H25>=4.5,4,IF(H25>=3.8,3,IF(H25>=3,2,1))) -> 1 | H25: =EVALUACION!H32 -> 0
B26: Generación de modelos de IA. | C26: Se implementan y comparan múltiples modelos o configuraciones con control detallado de hiperparámetros, regularización, validación cruzada y manejo de sesgos. | D26: Se generan uno o más modelos funcionales, aplicando correctamente técnicas de entrenamiento, validación y ajuste básico de hiperparámetros. | E26: Se genera al menos un modelo de IA funcional, pero con implementación limitada o poco optimizada. | F26: No se logra generar un modelo funcional o el proceso presenta errores críticos. | G26: =IF(H26>=4.5,4,IF(H26>=3.8,3,IF(H26>=3,2,1))) -> 1 | H26: =EVALUACION!H33 -> 0
B27: Estrategias de optimización para cada modelo. | C27: Se implementa un enfoque riguroso y sistemático de optimización, como búsqueda en malla (Grid Search), aleatoria (Random Search), Bayesian Optimization o AutoML. | D27: Se evidencia mejora real en el rendimiento del modelo como resultado de la optimización. La metodología no es muy rigurosa, pero define unos pasos mínimos. | E27: Se intenta alguna forma de optimización (por ejemplo, cambio de un hiperparámetro), pero sin metodología clara. | F27: No se realiza ninguna optimización del modelo o se hace de forma incorrecta. | G27: =IF(H27>=4.5,4,IF(H27>=3.8,3,IF(H27>=3,2,1))) -> 1 | H27: =EVALUACION!H34 -> 0
B28: Comparativo de los modelos de IA a través de la discusión y análisis desde las métricas de desempeño. | C28: Se realiza una comparación profunda, crítica y bien estructurada entre todos los modelos implementados. Se analizan posibles razones del comportamiento de cada modelo y se interpretan los resultados con rigor técnico. | D28: Se comparan adecuadamente múltiples modelos utilizando varias métricas relevantes. La discusión es clara, con interpretación lógica de los resultados y su relación con el tipo de problema. | E28: Se realiza una comparación básica entre modelos, pero sin una discusión clara o con argumentos débiles. | F28: No se realiza ningún tipo de comparación entre modelos. | G28: =IF(H28>=4.5,4,IF(H28>=3.8,3,IF(H28>=3,2,1))) -> 1 | H28: =EVALUACION!H35 -> 0
B29: VoBO y feedback del stakeholder del sector industria. | C29: Se demuestra alineación entre los resultados del proyecto y las necesidades estratégicas o operativas del sector involucrado | D29: Se demuestra que el modelo o solución se adapta razonablemente a los requerimientos del entorno real. | E29: No queda claro si la solución cumple con las necesidades reales del entorno industrial. | F29: No se incluye ningún tipo de retroalimentación por parte del stakeholder. | G29: =IF(H29>=4.5,4,IF(H29>=3.8,3,IF(H29>=3,2,1))) -> 1 | H29: =EVALUACION!H36 -> 0
A30: Sustentación | B30: Presentación e Introducción | C30: El orador se presenta a la audiencia, identifica el tema y establece claramente el objetivo de la presentación | D30: El orador se presenta a la audiencia, identifica el tema y establece parcialmente el objetivo de la presentación | E30: El orador se presenta a la audiencia, identifica parcialmente el tema y el objetivo de la presentación | F30: El orador se presenta a la audiencia, identifica el tema , pero omite el objetivo de la presentación | G30: =IF(H30>=4.5,4,IF(H30>=3.8,3,IF(H30>=3,2,1))) -> 1 | H30: =EVALUACION!H37 -> 0
B31: Estructura de la presentación | C31: El orador comunica a la audiencia la estructura de la presentación. La estructura sigue una secuencia lógica (introducción, contenido, conclusión) y en ella, el orador sigue la estructura propuesta | D31: El orador comunica a la audiencia la estructura de la presentación. La estructura sigue una secuencia lógica (introducción, contenido, conclusión). Sin embargo, durante la presentación, el orador se aparta de la | E31: El orador comunica a la audiencia la estructura de la presentación, la sigue durante la presentación, pero no resulta apreciable una secuencia lógica. | F31: El orador presenta la estructura de la presentación a la audiencia, pero no la sigue, ni establece una secuencia lógica para ser presentada a la audiencia | G31: =IF(H31>=4.5,4,IF(H31>=3.8,3,IF(H31>=3,2,1))) -> 1 | H31: =EVALUACION!H38 -> 0
B32: Dominio del Contenido y defensa de argumentos. | C32: Expresa las ideas con claridad y fluidez identificando los aspectos centrales y secundarios del tema | D32: Expresa las ideas con claridad, identificando los aspectos centrales y secundarios del tema. Sin embargo, la fluidez de la presentación ofrece oportunidades de | E32: Expresa las ideas identificando los aspectos centrales y secundarios del tema. Sin embargo, la claridad y la fluidez de la presentación ofrecen oportunidades de mejora | F32: Expresa las ideas sin identificar los aspectos centrales y secundarios del tema. Sin claridad y fluidez en la presentación. | G32: =IF(H32>=4.5,4,IF(H32>=3.8,3,IF(H32>=3,2,1))) -> 1 | H32: =EVALUACION!H39 -> 0
B33: Conclusiones y cierre de la presentación | C33: Presenta conclusiones significativas de la presentación, responde las preguntas del auditorio de forma clara y precisa | D33: Presenta conclusiones de la presentación, responde las preguntas del auditorio con algunas ambiguedades o imprecisiones | E33: Presenta conclusiones de la presentación, responde las preguntas del auditorio de forma imprecisa o errónea. | F33: Presenta parcialmente las conclusiones de la presentación, no responde adecuadamente a las preguntas del auditorio. | G33: =IF(H33>=4.5,4,IF(H33>=3.8,3,IF(H33>=3,2,1))) -> 1 | H33: =EVALUACION!H40 -> 0

Sheet MAPEO
C2: Facultad de Ingeniería y Diseño - Maestría en Ciencia de Datos/Inteligencia Artificial Aplicada - Evaluación Proyecto II de innovación tecnológica en IA
B8: EVALUACIÓN
B11: Criterio | C11: Detalle | D11: Competencia/Resultado Aprendizaje
B12: =EVALUACION!B18 -> Escritura del documento | C12: =EVALUACION!F18 -> Ortografía, vocabulario, gramática. | D12: C1,RA1
C13: =EVALUACION!F19 -> Cohesión y coherencia. | D13: C1,RA1
C14: =EVALUACION!F20 -> Citaciones y Bibliografía
C15: =EVALUACION!F21 -> Estructura IMRC
B16: =EVALUACION!B22 -> Fundamentación Teórica | C16: =EVALUACION!F22 -> Marco Teórico | D16: C3,RA1
C17: =EVALUACION!F23 -> Estado del Arte | D17: C3,RA1
B18: =EVALUACION!B24 -> Constitución del proyecto | C18: =EVALUACION!F24 -> Formulación del Problema de Negocio (motivación y antecedentes). | D18: C3,RA1
C19: =EVALUACION!F25 -> Objetivos | D19: C3,RA1
C20: =EVALUACION!F26 -> Metodología | D20: C3,RA1
B21: =EVALUACION!B27 -> Aplicación de Ciencia de Datos | C21: =EVALUACION!F27 -> Selección y estudio de viabilidad del dataset para un proyecto de ciencias de datos. | D21: C4,RA1
C22: =EVALUACION!F28 -> Identificación del tipo de problema y del paradigma de IA adecuado para abordarlo. | D22: C4,RA1
C23: =EVALUACION!F29 -> Revisión y justificación sobre el proceso de selección y descarte de features. | D23: C4,RA1
C24: =EVALUACION!F30 -> Acciones de preprocesamiento y su justificación. | D24: C4,RA1
C25: =EVALUACION!F31 -> Selección y justificación de los algoritmos de entrenamiento. | D25: C4,RA1
C26: =EVALUACION!F32 -> Selección y justificación de las métricas de desempeño. | D26: C4,RA1
C27: =EVALUACION!F33 -> Generación de modelos de IA. | D27: C4,RA1
C28: =EVALUACION!F34 -> Estrategias de optimización para cada modelo. | D28: C4,RA1
C29: =EVALUACION!F35 -> Comparativo de los modelos de IA a través de la discusión y análisis desde las métricas de desempeño. | D29: C4,RA1
C30: =EVALUACION!F36 -> VoBO y feedback del stakeholder del sector industria. | D30: C1,RA2
B31: =EVALUACION!B37 -> Sustentación | C31: =EVALUACION!F37 -> Presentación e Introducción
C32: =EVALUACION!F38 -> Estructura de la presentación | D32: C1,RA1
C33: =EVALUACION!F39 -> Dominio del Contenido y defensa de argumentos.
C34: =EVALUACION!F40 -> Conclusiones y cierre de la presentación
B36: Assessment | C36: Mapeo Competencias, Resultados de Aprendizaje e Indicadores de Desempeño | D36: Competencia | E36: Resultado de Aprendizaje | F36: Indicador de Desempeño
D37: Competencia 1: Comunicación Efectiva Comunicarse adecuadamente usando canales y medios ajustados al mensaje y a la audiencia, y facilitando el intercambio de información. | E37: RA1. Seleccionar el canal de comunicación apropiado dependiendo de la audiencia. | F37: =C32 -> Estructura de la presentación
F38: =C12 -> Ortografía, vocabulario, gramática.
F39: =C13 -> Cohesión y coherencia.
E40: RA2. Facilitar el intercambio de información con otros profesionales y actores de la sociedad. | F40: =C30 -> VoBO y feedback del stakeholder del sector industria.
D41: Competencia 3: Solución de Problemas: Solucionar problemas complejos usando pensamiento sistémico e información relevante. | E41: RA1. Examinar problemas complejos aplicando el pensamiento sistémico y plantear soluciones basadas en conocimiento e información relevante. | F41: =C16 -> Marco Teórico
F42: =C17 -> Estado del Arte
F43: =C18 -> Formulación del Problema de Negocio (motivación y antecedentes).
F44: =C19 -> Objetivos
F45: =C20 -> Metodología
D46: Competencia 4: Análisis de información: Utilizar análisis de datos, técnicas estadísticas y aprendizaje automático sobre datos e información disponible para descubrir relaciones y obtener un mejor entendimiento de los problemas y los procesos organizacionales, con el fin de respaldar la toma de decisiones. | E46: RA1. Examinar conjuntos de datos aplicando técnicas estadísticas y aprendizaje automático con el fin de tomar decisiones informadas soportadas en datos. | F46: =C21 -> Selección y estudio de viabilidad del dataset para un proyecto de ciencias de datos.
F47: =C22 -> Identificación del tipo de problema y del paradigma de IA adecuado para abordarlo.
F48: =C23 -> Revisión y justificación sobre el proceso de selección y descarte de features.
F49: =C24 -> Acciones de preprocesamiento y su justificación.
...

Sheet ASSESSMENT
C2: Facultad de Ingeniería y Diseño - Maestría en Ciencia de Datos/Inteligencia Artificial Aplicada - Evaluación Proyecto II de innovación tecnológica en IA
B8: EVALUACIÓN
B10: Competencia | C10: Resultado de Aprendizaje | D10: Indicador de Desempeño | E10: Valoración | F10: Nivel | G10: Interpretación
B11: Competencia 1: Comunicación Efectiva Comunicarse adecuadamente usando canales y medios ajustados al mensaje y a la audiencia, y facilitando el intercambio de información. | C11: RA1. Seleccionar el canal de comunicación apropiado dependiendo de la audiencia. | D11: =MAPEO!F37 -> Estructura de la presentación | E11: =Rúbrica!H31 -> 0 | F11: =IF(E11>=4.5,4,IF(E11>=3.8,3,(IF(E11>=3,2,1)))) -> 1 | G11: =IF(E11>=4.5,"Excede el Estándar",IF(E11>=3.8,"Logra el Estándar",IF(E11>=3,"Se acerca al estándar","NO cumple con el Estándar"))) -> NO cumple con el Estándar
D12: =MAPEO!F38 -> Ortografía, vocabulario, gramática. | E12: =Rúbrica!H11 -> 0 | F12: =IF(E12>=4.5,4,IF(E12>=3.8,3,(IF(E12>=3,2,1)))) -> 1 | G12: =IF(E12>=4.5,"Excede el Estándar",IF(E12>=3.8,"Logra el Estándar",IF(E12>=3,"Se acerca al estándar","NO cumple con el Estándar"))) -> NO cumple con el Estándar
D13: =MAPEO!F39 -> Cohesión y coherencia. | E13: =Rúbrica!H12 -> 0 | F13: =IF(E13>=4.5,4,IF(E13>=3.8,3,(IF(E13>=3,2,1)))) -> 1 | G13: =IF(E13>=4.5,"Excede el Estándar",IF(E13>=3.8,"Logra el Estándar",IF(E13>=3,"Se acerca al estándar","NO cumple con el Estándar"))) -> NO cumple con el Estándar
C14: RA2. Facilitar el intercambio de información con otros profesionales y actores de la sociedad. | D14: =MAPEO!F40 -> VoBO y feedback del stakeholder del sector industria. | E14: =Rúbrica!H29 -> 0 | F14: =IF(E14>=4.5,4,IF(E14>=3.8,3,(IF(E14>=3,2,1)))) -> 1 | G14: =IF(E14>=4.5,"Excede el Estándar",IF(E14>=3.8,"Logra el Estándar",IF(E14>=3,"Se acerca al estándar","NO cumple con el Estándar"))) -> NO cumple con el Estándar
B15: Competencia 3: Solución de Problemas: Solucionar problemas complejos usando pensamiento sistémico e información relevante. | C15: RA1. Examinar problemas complejos aplicando el pensamiento sistémico y plantear soluciones basadas en conocimiento e información relevante. | D15: =MAPEO!F41 -> Marco Teórico | E15: =Rúbrica!H15 -> 0 | F15: =IF(E15>=4.5,4,IF(E15>=3.8,3,(IF(E15>=3,2,1)))) -> 1 | G15: =IF(E15>=4.5,"Excede el Estándar",IF(E15>=3.8,"Logra el Estándar",IF(E15>=3,"Se acerca al estándar","NO cumple con el Estándar"))) -> NO cumple con el Estándar
D16: =MAPEO!F42 -> Estado del Arte | E16: =Rúbrica!H16 -> 0 | F16: =IF(E16>=4.5,4,IF(E16>=3.8,3,(IF(E16>=3,2,1)))) -> 1 | G16: =IF(E16>=4.5,"Excede el Estándar",IF(E16>=3.8,"Logra el Estándar",IF(E16>=3,"Se acerca al estándar","NO cumple con el Estándar"))) -> NO cumple con el Estándar
D17: =MAPEO!F43 -> Formulación del Problema de Negocio (motivación y antecedentes). | E17: =Rúbrica!H17 -> 0 | F17: =IF(E17>=4.5,4,IF(E17>=3.8,3,(IF(E17>=3,2,1)))) -> 1 | G17: =IF(E17>=4.5,"Excede el Estándar",IF(E17>=3.8,"Logra el Estándar",IF(E17>=3,"Se acerca al estándar","NO cumple con el Estándar"))) -> NO cumple con el Estándar
D18: =MAPEO!F44 -> Objetivos | E18: =Rúbrica!H18 -> 0 | F18: =IF(E18>=4.5,4,IF(E18>=3.8,3,(IF(E18>=3,2,1)))) -> 1 | G18: =IF(E18>=4.5,"Excede el Estándar",IF(E18>=3.8,"Logra el Estándar",IF(E18>=3,"Se acerca al estándar","NO cumple con el Estándar"))) -> NO cumple con el Estándar
B19: Competencia 4: Análisis de información: Utilizar análisis de datos, técnicas estadísticas y aprendizaje automático sobre datos e información disponible para descubrir relaciones y obtener un mejor entendimiento de los problemas y los procesos organizacionales, con el fin de respaldar la toma de decisiones. | C19: RA1. Examinar conjuntos de datos aplicando técnicas estadísticas y aprendizaje automático con el fin de tomar decisiones informadas soportadas en datos. | D19: =MAPEO!F45 -> Metodología | E19: =Rúbrica!H19 -> 0 | F19: =IF(E19>=4.5,4,IF(E19>=3.8,3,(IF(E19>=3,2,1)))) -> 1 | G19: =IF(E19>=4.5,"Excede el Estándar",IF(E19>=3.8,"Logra el Estándar",IF(E19>=3,"Se acerca al estándar","NO cumple con el Estándar"))) -> NO cumple con el Estándar
D20: =MAPEO!F46 -> Selección y estudio de viabilidad del dataset para un proyecto de ciencias de datos. | E20: =Rúbrica!H20 -> 0 | F20: =IF(E20>=4.5,4,IF(E20>=3.8,3,(IF(E20>=3,2,1)))) -> 1 | G20: =IF(E20>=4.5,"Excede el Estándar",IF(E20>=3.8,"Logra el Estándar",IF(E20>=3,"Se acerca al estándar","NO cumple con el Estándar"))) -> NO cumple con el Estándar
D21: =MAPEO!F47 -> Identificación del tipo de problema y del paradigma de IA adecuado para abordarlo. | E21: =Rúbrica!H21 -> 0 | F21: =IF(E21>=4.5,4,IF(E21>=3.8,3,(IF(E21>=3,2,1)))) -> 1 | G21: =IF(E21>=4.5,"Excede el Estándar",IF(E21>=3.8,"Logra el Estándar",IF(E21>=3,"Se acerca al estándar","NO cumple con el Estándar"))) -> NO cumple con el Estándar
D22: =MAPEO!F48 -> Revisión y justificación sobre el proceso de selección y descarte de features. | E22: =Rúbrica!H22 -> 0 | F22: =IF(E22>=4.5,4,IF(E22>=3.8,3,(IF(E22>=3,2,1)))) -> 1 | G22: =IF(E22>=4.5,"Excede el Estándar",IF(E22>=3.8,"Logra el Estándar",IF(E22>=3,"Se acerca al estándar","NO cumple con el Estándar"))) -> NO cumple con el Estándar
D23: =MAPEO!F49 -> Acciones de preprocesamiento y su justificación. | E23: =Rúbrica!H23 -> 0 | F23: =IF(E23>=4.5,4,IF(E23>=3.8,3,(IF(E23>=3,2,1)))) -> 1 | G23: =IF(E23>=4.5,"Excede el Estándar",IF(E23>=3.8,"Logra el Estándar",IF(E23>=3,"Se acerca al estándar","NO cumple con el Estándar"))) -> NO cumple con el Estándar
D24: =MAPEO!F50 -> Selección y justificación de los algoritmos de entrenamiento. | E24: =Rúbrica!H24 -> 0 | F24: =IF(E24>=4.5,4,IF(E24>=3.8,3,(IF(E24>=3,2,1)))) -> 1 | G24: =IF(E24>=4.5,"Excede el Estándar",IF(E24>=3.8,"Logra el Estándar",IF(E24>=3,"Se acerca al estándar","NO cumple con el Estándar"))) -> NO cumple con el Estándar
D25: =MAPEO!F51 -> Selección y justificación de las métricas de desempeño. | E25: =Rúbrica!H25 -> 0 | F25: =IF(E25>=4.5,4,IF(E25>=3.8,3,(IF(E25>=3,2,1)))) -> 1 | G25: =IF(E25>=4.5,"Excede el Estándar",IF(E25>=3.8,"Logra el Estándar",IF(E25>=3,"Se acerca al estándar","NO cumple con el Estándar"))) -> NO cumple con el Estándar
D26: =MAPEO!F52 -> Generación de modelos de IA. | E26: =Rúbrica!H26 -> 0 | F26: =IF(E26>=4.5,4,IF(E26>=3.8,3,(IF(E26>=3,2,1)))) -> 1 | G26: =IF(E26>=4.5,"Excede el Estándar",IF(E26>=3.8,"Logra el Estándar",IF(E26>=3,"Se acerca al estándar","NO cumple con el Estándar"))) -> NO cumple con el Estándar
D27: =MAPEO!F53 -> Estrategias de optimización para cada modelo. | E27: =Rúbrica!H27 -> 0 | F27: =IF(E27>=4.5,4,IF(E27>=3.8,3,(IF(E27>=3,2,1)))) -> 1 | G27: =IF(E27>=4.5,"Excede el Estándar",IF(E27>=3.8,"Logra el Estándar",IF(E27>=3,"Se acerca al estándar","NO cumple con el Estándar"))) -> NO cumple con el Estándar
D28: =MAPEO!F54 -> Comparativo de los modelos de IA a través de la discusión y análisis desde las métricas de desempeño. | E28: =Rúbrica!H28 -> 0 | F28: =IF(E28>=4.5,4,IF(E28>=3.8,3,(IF(E28>=3,2,1)))) -> 1 | G28: =IF(E28>=4.5,"Excede el Estándar",IF(E28>=3.8,"Logra el Estándar",IF(E28>=3,"Se acerca al estándar","NO cumple con el Estándar"))) -> NO cumple con el Estándar

Sheet Rúbrica_JURADO
C3: Facultad de Ingeniería- Departamento Tecnologías de Información y Comunicaciones Evaluación del Trabajo de Grado
B9: Presentación Oral | C9: JURADO
B12: Niveles de Proficiencia | C12: Nivel 4: Accomplished | D12: Nivel 3: Proficient | E12: Nivel 2: Developing | F12: Nivel 1: Beginning | G12: Nivel de Proficiencia alcanzado
B13: Valor Numérico | C13: 5,0-4,5 | D13: 4,4 - 3,8 | E13: 3,7- 3,0 | F13: 2,9 - 1.0 | H13: Valor Numérico
B14: Presentación e Introducción | C14: El orador se presenta a la audiencia, identifica el tema y establece claramente el objetivo de la presentación | D14: El orador se presenta a la audiencia, identifica el tema y establece parcialmente el objetivo de la presentación | E14: El orador se presenta a la audiencia, identifica parcialmente el tema y el objetivo de la presentación | F14: El orador se presenta a la audiencia, identifica el tema , pero omite el objetivo de la presentación | G14: =IF(H14>4.7,4,IF(H14>=4,3,IF(H14>=3.4,2,1))) -> 1 | H14: 0
B15: Estructura de la presentación | C15: El orador comunica a la audiencia la estructura de la presentación. La estructura sigue una secuencia lógica (introducción, contenido, conclusión) y en ella, el orador sigue la estructura propuesta | D15: El orador comunica a la audiencia la estructura de la presentación. La estructura sigue una secuencia lógica (introducción, contenido, conclusión). Sin embargo, durante la presentación, el orador se aparta de la estructura propuesta | E15: El orador comunica a la audiencia la estructura de la presentación, la sigue durante la presentación, pero no resulta apreciable una secuencia lógica. | F15: El orador presenta la estructura de la presentación a la audiencia, pero no la sigue, ni establece una secuencia lógica para ser presentada a la audiencia | G15: =IF(H15>4.7,4,IF(H15>=4,3,IF(H15>=3.4,2,1))) -> 1 | H15: 0
B16: Dominio del contenido de la presentación | C16: Expresa las ideas con claridad y fluidez identificando los aspectos centrales y secundarios del tema | D16: Expresa las ideas con claridad, identificando los aspectos centrales y secundarios del tema. Sin embargo, la fluidez de la presentación ofrece oportunidades de mejora | E16: Expresa las ideas identificando los aspectos centrales y secundarios del tema. Sin embargo, la claridad y la fluidez de la presentación ofrecen oportunidades de mejora | F16: Expresa las ideas sin identificar los aspectos centrales y secundarios del tema. Sin claridad y fluidez en la presentación. | G16: =IF(H16>4.7,4,IF(H16>=4,3,IF(H16>=3.4,2,1))) -> 1 | H16: 0
B17: Vocabulario | C17: Utiliza un lenguaje claro y preciso que favorece la efectividad de la presentación. El lenguaje resulta apropiado a la audiencia objetivo de la presentación | D17: Utiliza un lenguaje claro que favorece la efectividad en la presentación de las ideas, evidencia algunas imprecisiones en la presentación de las ideas, pero resulta apropiado para la audiencia objetivo de la presentación | E17: Utiliza un lenguaje claro que favorece la efectividad en la presentación de las ideas, evidencia muchas imprecisiones en la presentación de las ideas, pero resulta apropiado para la audiencia objetivo de la presentación | F17: Utiliza un lenguaje confuso, que soporta en forma mínima la efectividad de la presentación. El lenguaje de la presentación no resulta apropiado a la audiencia. | G17: =IF(H17>4.7,4,IF(H17>=4,3,IF(H17>=3.4,2,1))) -> 1 | H17: 0
B18: Empleo de material de apoyo | C18: Utiliza materiales de apoyo (explicaciones, ejemplos ilustraciones, estadísticas, analogías, citas de fuentes relevantes) que favorecen y refuerzan la efectividad de la presentación | D18: Utiliza materiales de apoyo (explicaciones, ejemplos ilustraciones, estadísticas, analogías, citas de fuentes relevantes) que soportan la presentación | E18: Utiliza materiales de apoyo (explicaciones, ejemplos ilustraciones, estadísticas, analogías, citas de fuentes relevantes) con la intención de soportar la presentación. Sin embargo, la presencia de algunos de ellos, entorpece/oscurece la presentación | F18: Ausencia de materiales de apoyo (explicaciones, ejemplos ilustraciones, estadísticas, analogías, citas de fuentes relevantes) que favorezcan de algún modo la presentación | G18: =IF(H18>4.7,4,IF(H18>=4,3,IF(H18>=3.4,2,1))) -> 1 | H18: 0
B19: Uso de Herramientas Electrónicas para la presentación | C19: La presentación utiliza herramientas electrónicas. Los recursos utilizados favorecen/refuerzan su contenido; el tipo de letra y las imágenes apoyan la presentación; en las diapositivas el texto identifica las ideas principales y no está sobrecargado. | D19: La presentación utiliza herramientas electrónicas. Los recursos utilizados favorecen/refuerzan su contenido; el tipo de letra y las imágenes NO apoyan la presentación; en las diapositivas el texto identifica las ideas principales y no está sobrecargado. | E19: La presentación utiliza herramientas electrónicas. Los recursos utilizados favorecen/refuerzan su contenido; el tipo de letra y las imágenes NO apoyan la presentación; en las diapositivas el texto identifica las ideas principales y está sobrecargado. | F19: La presentación utiliza herramientas electrónicas, pero los recursos utilizados favorecen/refuerzan DÉBILMENTE su contenido; el tipo de letra y las imágenes NO apoyan la presentación; en las diapositivas el texto identifica las ideas principales y está sobrecargado. | G19: =IF(H19>4.7,4,IF(H19>=4,3,IF(H19>=3.4,2,1))) -> 1 | H19: 0
B20: Conclusiones y cierre de la presentación | C20: Presenta conclusiones significativas de la presentación, responde las preguntas del auditorio de forma clara y precisa | D20: Presenta conclusiones de la presentación, responde las preguntas del auditorio con algunas ambiguedades o imprecisiones | E20: Presenta conclusiones de la presentación, responde las preguntas del auditorio de forma imprecisa o errónea. | F20: Presenta parcialmente las conclusiones de la presentación, no responde adecuadamente a las preguntas del auditorio. | G20: =IF(H20>4.7,4,IF(H20>=4,3,IF(H20>=3.4,2,1))) -> 1 | H20: 0
B23: Defensa Argumentos | C23: JURADO
B26: Niveles de Proficiencia | C26: Nivel 4: Accomplished | D26: Nivel 3: Proficient | E26: Nivel 2: Developing | F26: Nivel 1: Beginning | G26: Nivel de Proficiencia alcanzado
B27: Valor Numérico | C27: 5,0-4,5 | D27: 4,4 - 3,8 | E27: 3,7- 3,0 | F27: 2,9 - 1.0 | H27: Valor Numérico
B28: Defensa de Argumentos | C28: Formula las premisas de la argumentación y sus relaciones. Las premisas sustentan suficientemente la conclusión. | D28: Formula las premisas y las relaciones entre ellas. Las premisas no sustentan suficientemente la conclusión. | E28: Formula las premisas y la conclusión, pero no las relaciona adecuadamente. | F28: Formula las premisas, pero la conclusión está inadecuadamente establecida | G28: =IF(H28>=4.7,4,IF(H28>=4,3,IF(H28>=3.4,2,1))) -> 1 | H28: 0

Sheet Rubrica Seguimiento
B2: Facultad de Ingeniería- Departamento Tecnologías de Información y Comunicaciones Evaluación del Trabajo de Grado
A8: Seguimiento | B8: Profesor PDG
A9: Niveles de Proficiencia | B9: Nivel 4: Accomplished | C9: Nivel 3:Proficient | D9: Nivel 2: Developing | E9: Nivel 1: Beginning | J9: Nivel de Proficiencia alcanzado
A10: Valor Numérico | B10: 5,0-4,5 | C10: 4,4-4,0 | D10: 3,9-3,0 | E10: 2,9-1,0 | F10: Segunda - Agosto 6 | G10: Tercera - Sept 17 | H10: Cuarta - Oct 8 | I10: Quinta - 19 de Nov | J10: (de 1 a 4) | K10: Valor Numérico
A11: Presentación | B11: La presentación es organizada, las ideas son expresadas con claridad y fluidez identificando los aspectos centrales y secundarios del tema | C11: La presentación es organizada, hay vacíos en la organización e identificando los aspectos centrales y secundarios del tema | D11: La presentación tiene algún grado de organización, hay vacíos en la organización y en la identificación y presentaciín de los aspectos centrales y secundarios del tema | E11: La presentación tiene poca organización, hay muchos vacíos en la organización y en la identificación y presentaciín de los aspectos centrales y secundarios del tema
A12: Cumplimiento de cronograma | B12: El gronograma se esta cumpliento según lo pleneado. No hay retrasos ni tareas pendientes sin justificación | C12: El gronograma se esta cumpliento en su mayor parte según lo planeado. Hay algunos retrasos o tareas pendientes. | D12: El gronograma se esta cumpliento con parte de lo planeado. Hay retrasos o tareas pendientes. | E12: El gronograma no se esta cumpliento según lo pleneado. Hay pocos avances.
A15: Cumplimiento de requisitos | B15: PDG
A17: Aspecto | B17: Si/No
A18: El trabajo cumple con todos los requisitos Eticos y Legales. En caso necesitar revisión por el comité ético se deberá someter al disctamen de este.

Sheet Hoja1

Sheet Matriz de cruce Meritorio
A1: Aspectos a evaluar / Evaluador | B1: Profesor PDG | C1: Tutor | D1: Lector | E1: Comité | F1: Comentario
A2: a) Pertinencia y alcance del problema de investigación propuesto. Coherencia de las preguntas de investigación con el problema planteado. | C2: X | D2: X | F2: Rubrica del Tutor: analisis de estado del arte, Marco teórico y antecedentes. Rubrica del Lector: Formulación del Problema.
A3: b) Cumplimiento de los objetivos propuestos. | D3: X | F3: Rubrica del Lector: Objetivos Metodología Contribución del Proyecto Conclusiones y Resultados
A4: c) Dominio del tema consignado en el marco teórico y calidad de la revisión bibliográfica incluida en el documento. | C4: X | D4: X | F4: Rubrica del Tutor: analisis de estado del arte, Marco teórico y antecedentes. Rubrica del Lector: Formulación del Problema, Metodología
A5: d) Pertinencia y validez del diseño metodológico empleado en la investigación. | D5: X | F5: Rubrica del Tutor y del Lector
A6: e) Calidad de la recolección, interpretación y análisis de los datos. | C6: X | D6: X | F6: Rubrica del Lector: Objetivos Metodología Contribución del Proyecto Conclusiones y Resultados
A7: f) Validez, alcance e impacto de los resultados y conclusiones. | C7: X | D7: X | F7: Rubrica del Tutor y Rubrica del Lector:Contribución del Proyecto Conclusiones y Resultados
A8: g) Calidad y cumplimiento de las normas vigentes para la presentación del informe escrito. | C8: X | D8: X | F8: Rubrica del Tutor y del Lector
A9: h) Cumplimiento de los requisitos éticos y legales pertinentes al tipo de trabajo de grado. | B9: X | C9: X | D9: X | F9: Aspecto de cumpliemito en las tres rubricas
A10: i) Calidad de la sustentación del trabajo. | E10: X | F10: Rubrica del Jurado: Presentación e Introducción Estructura de la presentación Dominio del contenido de la presentación Vocabulario Empleo de material de apoyo Uso de Herramientas Electrónicas para la presentación Conclusiones y cierre de la presentación

Sheet Ribrica Meritoria
A1: Aspectos a evaluar / Evaluador | B1: Cumple de manera sobresaliente | C1: Cumple aceptablemente | D1: Cumple parcialmente | E1: No cumple
A2: Pertinencia y alcance del problema de investigación propuesto. | B2: El proyecto es pertinente y el problema de investigación propuesto se ha completado completamente, superando los objetivos esperados | C2: El proyecto es pertinente y el problema de investigación propuesto se ha completado en su mayoría. | D2: El proyecto es pertinente y el problema de investigación propuesto se ha completado aceptablemente. | E2: El proyecto es pertinente y el problema de investigación propuesto se ha completado parcialmente
A3: Coherencia de las preguntas de investigación con el problema planteado. | B3: Las preguntas de investigación planteadas son coherentes con el problema y contribuyeron plenamente al avance en su solución | C3: Las preguntas de investigación planteadas son coherentes en buena medida con el problema y contribuyeron aceptablementa a su solución | D3: Las preguntas de investigación planteadas son parcialmente coherentes con el problema y contribuyeron medianamente a su solución | E3: Las preguntas de investigación planteadas son parcialmente coherentes con el problema y contribuyeron parcialmente a su solución
A4: Cumplimiento de los objetivos propuestos. | B4: Todos los objetivos propuestos se cumplieron completamente y superaron los inicialmente planteados | C4: Los objetivos propuestos se cumplieron en su mayor parte | D4: Los objetivos propuestos se cumplieron parcialmente | E4: No se cumplieron completamente los objetivos propuestos
A5: Dominio del tema consignado en el marco teórico y calidad de la revisión bibliográfica incluida en el documento. | B5: Los estudiantes dominan el tema, han realizado una investigación exaustiva del tema propuesto y la bibliografía está completa y correctamente citada en el documento. | C5: Los estudiantes han alcanzado un buen dominio del tema. Ellos han realizado una investigación completa del tema propuesto y la bibliografía está citada correctamente en el documento. | D5: Los estudiantes han alcanzado un aceptable dominio del tema. Ellos han realizado una investigación aceptable del tema propuesto y la mayoría de la bibliografía está citada correctamente en el documento. | E5: Los estudiantes han no han alcanzado un aceptable dominio del tema. Ellos han realizado una investigación aceptable del tema propuesto y la una parte de la bibliografía está citada correctamente en el documento.
A6: Pertinencia y validez del diseño metodológico empleado en la investigación. | B6: El diseño metodológico del proyecto está muy bien realizado para abordar el tema de investigación | C6: El diseño metodológico del proyecto está bien realizado para abordar el tema de investigación | D6: El diseño metodológico del proyecto está aceptablemente realizado para abordar el tema de investigación | E6: El diseño metodológico del proyecto está deficientemente realizado para abordar el tema de investigación
A7: Calidad de la recolección, interpretación y análisis de los datos. | B7: La información recolectada es completa y los datos son de muy buena calidad por la rigurosa metodología utilizada | C7: La información recolectada es completa y los datos son de buena calidad. | D7: La información recolectada es aceptable y los datos recolectados son de mediana calidad. | E7: La información recolectada es deficiente y los datos recolectados son de baja calidad.
A8: Validez, alcance e impacto de los resultados y conclusiones. | B8: Los resultados del proyecto son válidos y las conclusiones del proyecto tienen alto impacto | C8: Los resultados del proyecto son de buena calidad y las conclusiones del proyecto son válidas y tienen buen impacto | D8: Los resultados del proyecto son aceptables y las conclusiones del proyecto son válidas y tienen mediano impacto | E8: Los resultados del proyecto son parcialmente válidos y las conclusiones del proyecto son válidas y tienen bajo impacto
A9: Calidad y cumplimiento de las normas vigentes para la presentación del informe escrito. | B9: El proyecto cumple completamente con las normas vigentes para la presentación del informe escrito | C9: El proyecto cumple con las normas vigentes para la presentación del informe escrito | D9: El proyecto cumple aceptablemente con las normas vigentes para la presentación del informe escrito | E9: El proyecto cumple parcialmente con las normas vigentes para la presentación del informe escrito
A10: Cumplimiento de los requisitos éticos y legales pertinentes al tipo de trabajo de grado. | B10: El proyecto cumple con todos los requisitos éticos y legales
A11: Calidad de la sustentación del trabajo. | B11: La sustentación del proyecto fue clara, las ideas se presentaron ordenadamente, se utilizó un buen material de apoyo. Se respondieron todas las preguntas ampliamentey con claridad. | C11: La sustentación del proyecto fue clara, las ideas se presentaron en su mayoría ordenadamente. Se respondieron la mayoría de las preguntas Se utilizó un buen material de apoyo | D11: La sustentación del proyecto fue clara, las ideas se presentaron en forma ordenada en su mayoría. Se respondieron las preguntas en forma aceptable. Se utilizó algun material de apoyo | E11: La sustentación del proyecto fue confusa, algunas de las ideas se presentaron en forma ordenada. Se respondieron las preguntas no en su totalidad. Se utilizó algun material de apoyo
